<robot name = "robot">
    <link name="Torso">
        <inertial>
            <origin xyz="3 3 1.5" rpy="0 0 0"/>
            <mass value="1" />
            <inertia ixx="100" ixy="0" ixz="0" iyy="100" iyz="0" izz="100" />
        </inertial>
        <visual>
            <origin xyz="3 3 1.5" rpy="0 0 0"/>
            <geometry>
                <box size="1 1 1" />
            </geometry>
            <material name="Cyan">
                <color rgba="0 1.0 1.0 1.0"/>
            </material>
        </visual>
        <collision>
            <origin xyz="3 3 1.5" rpy="0 0 0"/>
            <geometry>
                <box size="1 1 1" />
            </geometry>
        </collision>
    </link>
    <link name="leftFoot">
        <inertial>
            <origin xyz="0.5 0 -0.25" rpy="0 0 0"/>
            <mass value="1" />
            <inertia ixx="100" ixy="0" ixz="0" iyy="100" iyz="0" izz="100" />
        </inertial>
        <visual>
            <origin xyz="0.5 0 -0.25" rpy="0 0 0"/>
            <geometry>
                <box size="1 1 0.5" />
            </geometry>
            <material name="Cyan">
                <color rgba="0 1.0 1.0 1.0"/>
            </material>
        </visual>
        <collision>
            <origin xyz="0.5 0 -0.25" rpy="0 0 0"/>
            <geometry>
                <box size="1 1 0.5" />
            </geometry>
        </collision>
    </link>
    <link name="rightFoot">
        <inertial>
            <origin xyz="-1 0 -0.25" rpy="0 0 0"/>
            <mass value="1" />
            <inertia ixx="100" ixy="0" ixz="0" iyy="100" iyz="0" izz="100" />
        </inertial>
        <visual>
            <origin xyz="-1 0 -0.25" rpy="0 0 0"/>
            <geometry>
                <box size="2 1 0.5" />
            </geometry>
            <material name="Cyan">
                <color rgba="0 1.0 1.0 1.0"/>
            </material>
        </visual>
        <collision>
            <origin xyz="-1 0 -0.25" rpy="0 0 0"/>
            <geometry>
                <box size="2 1 0.5" />
            </geometry>
        </collision>
    </link>
    <link name="leftCrutch">
        <inertial>
            <origin xyz="0 0.5 -0.25" rpy="0 0 0"/>
            <mass value="1" />
            <inertia ixx="100" ixy="0" ixz="0" iyy="100" iyz="0" izz="100" />
        </inertial>
        <visual>
            <origin xyz="0 0.5 -0.25" rpy="0 0 0"/>
            <geometry>
                <box size="1 1 0.5" />
            </geometry>
            <material name="Cyan">
                <color rgba="0 1.0 1.0 1.0"/>
            </material>
        </visual>
        <collision>
            <origin xyz="0 0.5 -0.25" rpy="0 0 0"/>
            <geometry>
                <box size="1 1 0.5" />
            </geometry>
        </collision>
    </link>
    <link name="rightCrutch">
        <inertial>
            <origin xyz="0 -0.5 -0.25" rpy="0 0 0"/>
            <mass value="1" />
            <inertia ixx="100" ixy="0" ixz="0" iyy="100" iyz="0" izz="100" />
        </inertial>
        <visual>
            <origin xyz="0 -0.5 -0.25" rpy="0 0 0"/>
            <geometry>
                <box size="1 1 0.5" />
            </geometry>
            <material name="Cyan">
                <color rgba="0 1.0 1.0 1.0"/>
            </material>
        </visual>
        <collision>
            <origin xyz="0 -0.5 -0.25" rpy="0 0 0"/>
            <geometry>
                <box size="1 1 0.5" />
            </geometry>
        </collision>
    </link>
    <joint name="leftFoot_Torso" type="continuous">
       <parent link="Torso"/>
       <child  link="leftFoot"/>
       <origin rpy="0 0 0" xyz="3.5 3 1" />
       <axis xyz="0 1 0"/>
       <limit effort="0.0" lower="-3.14159" upper="3.14159" velocity="0.0"/>
    </joint>
    <joint name="rightFoot_Torso" type="revolute">
       <parent link="Torso"/>
       <child  link="rightFoot"/>
       <origin rpy="0 0 0" xyz="2.5 3 1" />
       <axis xyz="0 1 0"/>
       <limit effort="0.0" lower="-3.14159" upper="3.14159" velocity="0.0"/>
    </joint>
    <joint name="leftCrutch_Torso" type="revolute">
       <parent link="Torso"/>
       <child  link="leftCrutch"/>
       <origin rpy="0 0 0" xyz="3 3.5 1" />
       <axis xyz="0 1 0"/>
       <limit effort="0.0" lower="-3.14159" upper="3.14159" velocity="0.0"/>
    </joint>
    <joint name="rightCrutch_Torso" type="revolute">
       <parent link="Torso"/>
       <child  link="rightCrutch"/>
       <origin rpy="0 0 0" xyz="3 2.5 1" />
       <axis xyz="0 1 0"/>
       <limit effort="0.0" lower="-3.14159" upper="3.14159" velocity="0.0"/>
    </joint>
</robot>