<robot name = "robot">
    <link name="Foot1">
        <inertial>
            <origin xyz="0 0 0.5" rpy="0 0 0"/>
            <mass value="1" />
            <inertia ixx="100" ixy="0" ixz="0" iyy="100" iyz="0" izz="100" />
        </inertial>
        <visual>
            <origin xyz="0 0 0.5" rpy="0 0 0"/>
            <geometry>
                <box size="0.5 0.2 1" />
            </geometry>
            <material name="Cyan">
                <color rgba="0 1.0 1.0 1.0"/>
            </material>
        </visual>
        <collision>
            <origin xyz="0 0 0.5" rpy="0 0 0"/>
            <geometry>
                <box size="0.5 0.2 1" />
            </geometry>
        </collision>
    </link>
    <joint name="Foot1_Torso" type="revolute">
       <parent link="Foot1"/>
       <child  link="Torso"/>
       <origin rpy="0 0 0" xyz="0 0.4 1" />
       <axis xyz="0 1 0"/>
       <limit effort="0.0" lower="-3.14159" upper="3.14159" velocity="0.0"/>
    </joint>
    <link name="Torso">
        <inertial>
            <origin xyz="0.75 0 0.5" rpy="0 0 0"/>
            <mass value="1" />
            <inertia ixx="100" ixy="0" ixz="0" iyy="100" iyz="0" izz="100" />
        </inertial>
        <visual>
            <origin xyz="0.75 0 0.5" rpy="0 0 0"/>
            <geometry>
                <box size="2 1 1" />
            </geometry>
            <material name="Cyan">
                <color rgba="0 1.0 1.0 1.0"/>
            </material>
        </visual>
        <collision>
            <origin xyz="0.75 0 0.5" rpy="0 0 0"/>
            <geometry>
                <box size="2 1 1" />
            </geometry>
        </collision>
    </link>
    <joint name="Foot2_Torso" type="revolute">
       <parent link="Torso"/>
       <child  link="Foot2"/>
       <origin rpy="0 0 0" xyz="0 0.4 0" />
       <axis xyz="0 1 0"/>
       <limit effort="0.0" lower="-3.14159" upper="3.14159" velocity="0.0"/>
    </joint>
    <link name="Foot2">
        <inertial>
            <origin xyz="0 0 -0.5" rpy="0 0 0"/>
            <mass value="1" />
            <inertia ixx="100" ixy="0" ixz="0" iyy="100" iyz="0" izz="100" />
        </inertial>
        <visual>
            <origin xyz="0 0 -0.5" rpy="0 0 0"/>
            <geometry>
                <box size="0.5 0.2 1" />
            </geometry>
            <material name="Cyan">
                <color rgba="0 1.0 1.0 1.0"/>
            </material>
        </visual>
        <collision>
            <origin xyz="0 0 -0.5" rpy="0 0 0"/>
            <geometry>
                <box size="0.5 0.2 1" />
            </geometry>
        </collision>
    </link>
    <joint name="Foot3_Torso" type="revolute">
       <parent link="Torso"/>
       <child  link="Foot3"/>
       <origin rpy="0 0 0" xyz="1.5 0.4 0" />
       <axis xyz="0 1 0"/>
       <limit effort="0.0" lower="-3.14159" upper="3.14159" velocity="0.0"/>
    </joint>
    <link name="Foot3">
        <inertial>
            <origin xyz="0 0 -0.3" rpy="0 0 0"/>
            <mass value="1" />
            <inertia ixx="100" ixy="0" ixz="0" iyy="100" iyz="0" izz="100" />
        </inertial>
        <visual>
            <origin xyz="0 0 -0.3" rpy="0 0 0"/>
            <geometry>
                <box size="0.5 0.2 1" />
            </geometry>
            <material name="Cyan">
                <color rgba="0 1.0 1.0 1.0"/>
            </material>
        </visual>
        <collision>
            <origin xyz="0 0 -0.3" rpy="0 0 0"/>
            <geometry>
                <box size="0.5 0.2 1" />
            </geometry>
        </collision>
    </link>
    <joint name="Foot4_Torso" type="revolute">
       <parent link="Torso"/>
       <child  link="Foot4"/>
       <origin rpy="0 0 0" xyz="1.5 -0.4 0" />
       <axis xyz="0 1 0"/>
       <limit effort="0.0" lower="-3.14159" upper="3.14159" velocity="0.0"/>
    </joint>
    <link name="Foot4">
        <inertial>
            <origin xyz="0 0 -0.3" rpy="0 0 0"/>
            <mass value="1" />
            <inertia ixx="100" ixy="0" ixz="0" iyy="100" iyz="0" izz="100" />
        </inertial>
        <visual>
            <origin xyz="0 0 -0.3" rpy="0 0 0"/>
            <geometry>
                <box size="0.5 0.2 1" />
            </geometry>
            <material name="Cyan">
                <color rgba="0 1.0 1.0 1.0"/>
            </material>
        </visual>
        <collision>
            <origin xyz="0 0 -0.3" rpy="0 0 0"/>
            <geometry>
                <box size="0.5 0.2 1" />
            </geometry>
        </collision>
    </link>
</robot>